<?xml version="1.0" encoding="utf-8"?>
<!-- This URDF was automatically created by SolidWorks to URDF Exporter! Originally created by Stephen Brawner (brawner@gmail.com) 
     Commit Version: 1.6.0-1-g15f4949  Build Version: 1.6.7594.29634
     For more information, please see http://wiki.ros.org/sw_urdf_exporter -->
<robot
  name="hand_model">
  <link
    name="base_link">
    <inertial>
      <origin
        xyz="0.052456 -2.0159 0.10611"
        rpy="0 0 0" />
      <mass
        value="735.46" />
      <inertia
        ixx="352.42"
        ixy="20.774"
        ixz="0.0032309"
        iyy="49.499"
        iyz="0.011357"
        izz="382.81" />
    </inertial>
    <visual>
      <origin
        xyz="0 0 0"
        rpy="0 0 0" />
      <geometry>
        <mesh
          filename="meshes/base_link.STL" />
      </geometry>
      <material
        name="">
        <color
          rgba="0.79216 0.81961 0.93333 1" />
      </material>
    </visual>
    <collision>
      <origin
        xyz="0 0 0"
        rpy="0 0 0" />
      <geometry>
        <mesh
          filename="meshes/base_link.STL" />
      </geometry>
    </collision>
  </link>
  <link
    name="palm_link">
    <inertial>
      <origin
        xyz="0.033073 0.10668 -0.55909"
        rpy="0 0 0" />
      <mass
        value="182.12" />
      <inertia
        ixx="19.088"
        ixy="0.036455"
        ixz="1.151"
        iyy="31.521"
        iyz="-0.38093"
        izz="13.566" />
    </inertial>
    <visual>
      <origin
        xyz="0 0 0"
        rpy="0 0 0" />
      <geometry>
        <mesh
          filename="meshes/palm_link.STL" />
      </geometry>
      <material
        name="">
        <color
          rgba="0.79216 0.81961 0.93333 1" />
      </material>
    </visual>
    <collision>
      <origin
        xyz="0 0 0"
        rpy="0 0 0" />
      <geometry>
        <mesh
          filename="meshes/palm_link.STL" />
      </geometry>
    </collision>
  </link>
  <joint
    name="wrist"
    type="continuous">
    <origin
      xyz="-0.0407022845002883 -0.689999999999996 0.00656838564770951"
      rpy="1.5707963267949 0 -0.00890076335310535" />
    <parent
      link="base_link" />
    <child
      link="palm_link" />
    <axis
      xyz="0 1 0" />
  </joint>
  <link
    name="thumb_link">
    <inertial>
      <origin
        xyz="0.0583211409604228 0.173750872293611 -1.0568241727682E-05"
        rpy="0 0 0" />
      <mass
        value="6.47757871603702" />
      <inertia
        ixx="0.066710034410787"
        ixy="-1.00908741501593E-08"
        ixz="7.18235875721979E-10"
        iyy="0.0267709057361753"
        iyz="-8.31808962508795E-06"
        izz="0.0827471728041189" />
    </inertial>
    <visual>
      <origin
        xyz="0 0 0"
        rpy="0 0 0" />
      <geometry>
        <mesh
          filename="meshes/thumb_link.STL" />
      </geometry>
      <material
        name="">
        <color
          rgba="0.298039215686275 0.298039215686275 0.298039215686275 1" />
      </material>
    </visual>
    <collision>
      <origin
        xyz="0 0 0"
        rpy="0 0 0" />
      <geometry>
        <mesh
          filename="meshes/thumb_link.STL" />
      </geometry>
    </collision>
  </link>
  <joint
    name="thumb_palm"
    type="continuous">
    <origin
      xyz="-0.523008997433875 0.0804178268004505 -0.499404989881378"
      rpy="-1.74697481527175 1.10178968409712 0" />
    <parent
      link="palm_link" />
    <child
      link="thumb_link" />
    <axis
      xyz="1 0 0" />
  </joint>
  <link
    name="thumb_top_link">
    <inertial>
      <origin
        xyz="0.0585211412178711 0.18196595438193 -1.00513642356734E-05"
        rpy="0 0 0" />
      <mass
        value="6.8067193219922" />
      <inertia
        ixx="0.075982777275474"
        ixy="-9.74255523391448E-09"
        ixz="3.03012642212906E-10"
        iyy="0.0276285552963208"
        iyz="-8.82753070973629E-06"
        izz="0.0923367042054285" />
    </inertial>
    <visual>
      <origin
        xyz="0 0 0"
        rpy="0 0 0" />
      <geometry>
        <mesh
          filename="meshes/thumb_top_link.STL" />
      </geometry>
      <material
        name="">
        <color
          rgba="0.792156862745098 0.819607843137255 0.933333333333333 1" />
      </material>
    </visual>
    <collision>
      <origin
        xyz="0 0 0"
        rpy="0 0 0" />
      <geometry>
        <mesh
          filename="meshes/thumb_top_link.STL" />
      </geometry>
    </collision>
  </link>
  <joint
    name="thumb_finger_joint1"
    type="continuous">
    <origin
      xyz="0 0.376 0"
      rpy="0.137909370299002 0 0" />
    <parent
      link="thumb_link" />
    <child
      link="thumb_top_link" />
    <axis
      xyz="1 0 0" />
  </joint>
  <link
    name="index_Link">
    <inertial>
      <origin
        xyz="-0.0895117448846556 0.150984996742904 -1.46962151200691E-05"
        rpy="0 0 0" />
      <mass
        value="4.65304877999396" />
      <inertia
        ixx="0.0364961941236856"
        ixy="-3.71418203341085E-09"
        ixz="-8.22434564272086E-10"
        iyy="0.0149411534239804"
        iyz="-6.93591709387742E-06"
        izz="0.043734471629931" />
    </inertial>
    <visual>
      <origin
        xyz="0 0 0"
        rpy="0 0 0" />
      <geometry>
        <mesh
          filename="meshes/index_Link.STL" />
      </geometry>
      <material
        name="">
        <color
          rgba="0.298039215686275 0.298039215686275 0.298039215686275 1" />
      </material>
    </visual>
    <collision>
      <origin
        xyz="0 0 0"
        rpy="0 0 0" />
      <geometry>
        <mesh
          filename="meshes/index_Link.STL" />
      </geometry>
    </collision>
  </link>
  <joint
    name="index_palm"
    type="continuous">
    <origin
      xyz="-0.22804714819455 0.0804178268004546 -1.18100000000001"
      rpy="-1.94163099870294 0 0" />
    <parent
      link="palm_link" />
    <child
      link="index_Link" />
    <axis
      xyz="1 0 0" />
  </joint>
  <link
    name="index_mid_Link">
    <inertial>
      <origin
        xyz="-0.0891030233864157 0.125917463818585 -1.79756501640926E-05"
        rpy="0 0 0" />
      <mass
        value="3.80733854469799" />
      <inertia
        ixx="0.0219492247388545"
        ixy="-8.26517742386014E-09"
        ixz="-4.12725268451343E-10"
        iyy="0.0122249611057145"
        iyz="-5.39200278269389E-06"
        izz="0.0278683596848671" />
    </inertial>
    <visual>
      <origin
        xyz="0 0 0"
        rpy="0 0 0" />
      <geometry>
        <mesh
          filename="meshes/index_mid_Link.STL" />
      </geometry>
      <material
        name="">
        <color
          rgba="0.298039215686275 0.298039215686275 0.298039215686275 1" />
      </material>
    </visual>
    <collision>
      <origin
        xyz="0 0 0"
        rpy="0 0 0" />
      <geometry>
        <mesh
          filename="meshes/index_mid_Link.STL" />
      </geometry>
    </collision>
  </link>
  <joint
    name="index_finger_joint1"
    type="continuous">
    <origin
      xyz="-0.00060871447869093 0.326000000000002 0"
      rpy="0.702981876530976 0 0" />
    <parent
      link="index_Link" />
    <child
      link="index_mid_Link" />
    <axis
      xyz="1 0 0" />
  </joint>
  <link
    name="index_top_Link">
    <inertial>
      <origin
        xyz="-0.0889334703937087 0.151845872213121 -1.45652909617766E-05"
        rpy="0 0 0" />
      <mass
        value="4.69702723307249" />
      <inertia
        ixx="0.0366670220904177"
        ixy="-5.79987038292471E-09"
        ixz="2.56579029046409E-10"
        iyy="0.0149637358573457"
        iyz="-6.9853290293677E-06"
        izz="0.0438601528135111" />
    </inertial>
    <visual>
      <origin
        xyz="0 0 0"
        rpy="0 0 0" />
      <geometry>
        <mesh
          filename="meshes/index_top_Link.STL" />
      </geometry>
      <material
        name="">
        <color
          rgba="0.792156862745098 0.819607843137255 0.933333333333333 1" />
      </material>
    </visual>
    <collision>
      <origin
        xyz="0 0 0"
        rpy="0 0 0" />
      <geometry>
        <mesh
          filename="meshes/index_top_Link.STL" />
      </geometry>
    </collision>
  </link>
  <joint
    name="index_finger_joint2"
    type="continuous">
    <origin
      xyz="-0.000369553072763207 0.276 0"
      rpy="0.37375201122012 0 0" />
    <parent
      link="index_mid_Link" />
    <child
      link="index_top_Link" />
    <axis
      xyz="1 0 0" />
  </joint>
  <link
    name="middle_Link">
    <inertial>
      <origin
        xyz="-0.0775588935168185 0.174430532090828 -1.11140246791264E-05"
        rpy="0 0 0" />
      <mass
        value="6.15130656230038" />
      <inertia
        ixx="0.0634331507494948"
        ixy="-1.16548782140184E-08"
        ixz="8.65538356834223E-10"
        iyy="0.0234303176824209"
        iyz="-8.36131817532303E-06"
        izz="0.0766743128886783" />
    </inertial>
    <visual>
      <origin
        xyz="0 0 0"
        rpy="0 0 0" />
      <geometry>
        <mesh
          filename="meshes/middle_Link.STL" />
      </geometry>
      <material
        name="">
        <color
          rgba="0.298039215686275 0.298039215686275 0.298039215686275 1" />
      </material>
    </visual>
    <collision>
      <origin
        xyz="0 0 0"
        rpy="0 0 0" />
      <geometry>
        <mesh
          filename="meshes/middle_Link.STL" />
      </geometry>
    </collision>
  </link>
  <joint
    name="middle_palm"
    type="continuous">
    <origin
      xyz="0 0.080417826800454 -1.18100000000001"
      rpy="-2.02521229757416 0 0" />
    <parent
      link="palm_link" />
    <child
      link="middle_Link" />
    <axis
      xyz="1 0 0" />
  </joint>
  <link
    name="middle_mid_Link">
    <inertial>
      <origin
        xyz="-0.0773588868797277 0.149378250277068 -1.31476685010234E-05"
        rpy="0 0 0" />
      <mass
        value="5.20559573622676" />
      <inertia
        ixx="0.040676208942748"
        ixy="-1.30283680467504E-08"
        ixz="-4.94948432296105E-10"
        iyy="0.0198274885881821"
        iyz="-6.82301212607357E-06"
        izz="0.0518782639547025" />
    </inertial>
    <visual>
      <origin
        xyz="0 0 0"
        rpy="0 0 0" />
      <geometry>
        <mesh
          filename="meshes/middle_mid_Link.STL" />
      </geometry>
      <material
        name="">
        <color
          rgba="0.298039215686275 0.298039215686275 0.298039215686275 1" />
      </material>
    </visual>
    <collision>
      <origin
        xyz="0 0 0"
        rpy="0 0 0" />
      <geometry>
        <mesh
          filename="meshes/middle_mid_Link.STL" />
      </geometry>
    </collision>
  </link>
  <joint
    name="middle_finger_joint1"
    type="continuous">
    <origin
      xyz="0 0.376000000000001 0"
      rpy="0.794436157281628 0 0" />
    <parent
      link="middle_Link" />
    <child
      link="middle_mid_Link" />
    <axis
      xyz="1 0 0" />
  </joint>
  <link
    name="middle_top_Link">
    <inertial>
      <origin
        xyz="-0.0775588869211938 0.155178084349383 -1.25946103027852E-05"
        rpy="0 0 0" />
      <mass
        value="5.43182939965056" />
      <inertia
        ixx="0.0449837527864949"
        ixy="-7.45345717010324E-09"
        ixz="3.61017876062005E-10"
        iyy="0.0203442924201257"
        iyz="-7.18888681538327E-06"
        izz="0.05633254856514" />
    </inertial>
    <visual>
      <origin
        xyz="0 0 0"
        rpy="0 0 0" />
      <geometry>
        <mesh
          filename="meshes/middle_top_Link.STL" />
      </geometry>
      <material
        name="">
        <color
          rgba="0.792156862745098 0.819607843137255 0.933333333333333 1" />
      </material>
    </visual>
    <collision>
      <origin
        xyz="0 0 0"
        rpy="0 0 0" />
      <geometry>
        <mesh
          filename="meshes/middle_top_Link.STL" />
      </geometry>
    </collision>
  </link>
  <joint
    name="middle_finger_joint2"
    type="continuous">
    <origin
      xyz="0 0.326 0"
      rpy="0.14504 0 0" />
    <parent
      link="middle_mid_Link" />
    <child
      link="middle_top_Link" />
    <axis
      xyz="1 0 0" />
  </joint>
  <link
    name="ring_Link">
    <inertial>
      <origin
        xyz="0.0960915535849295 0.125917463800899 -1.79757202804498E-05"
        rpy="0 0 0" />
      <mass
        value="3.80733854451187" />
      <inertia
        ixx="0.0219492247988821"
        ixy="-3.07090627642851E-09"
        ixz="-3.92872722954063E-10"
        iyy="0.0122249611440997"
        iyz="-5.4011156421529E-06"
        izz="0.027868359747534" />
    </inertial>
    <visual>
      <origin
        xyz="0 0 0"
        rpy="0 0 0" />
      <geometry>
        <mesh
          filename="meshes/ring_Link.STL" />
      </geometry>
      <material
        name="">
        <color
          rgba="0.298039215686275 0.298039215686275 0.298039215686275 1" />
      </material>
    </visual>
    <collision>
      <origin
        xyz="0 0 0"
        rpy="0 0 0" />
      <geometry>
        <mesh
          filename="meshes/ring_Link.STL" />
      </geometry>
    </collision>
  </link>
  <joint
    name="ring_palm"
    type="continuous">
    <origin
      xyz="0.0499999999999973 0.080417826800454 -1.18100000000001"
      rpy="-1.93281935940357 0 0" />
    <parent
      link="palm_link" />
    <child
      link="ring_Link" />
    <axis
      xyz="1 0 0" />
  </joint>
  <link
    name="ring_mid_Link">
    <inertial>
      <origin
        xyz="0.0889902524601388 0.125917463818901 -1.79756899238298E-05"
        rpy="0 0 0" />
      <mass
        value="3.8073385446472" />
      <inertia
        ixx="0.0219492116432215"
        ixy="-5.69095821823743E-09"
        ixz="-1.47454084357904E-09"
        iyy="0.012224959060232"
        iyz="-5.39654250242922E-06"
        izz="0.0278683474793665" />
    </inertial>
    <visual>
      <origin
        xyz="0 0 0"
        rpy="0 0 0" />
      <geometry>
        <mesh
          filename="meshes/ring_mid_Link.STL" />
      </geometry>
      <material
        name="">
        <color
          rgba="0.298039215686275 0.298039215686275 0.298039215686275 1" />
      </material>
    </visual>
    <collision>
      <origin
        xyz="0 0 0"
        rpy="0 0 0" />
      <geometry>
        <mesh
          filename="meshes/ring_mid_Link.STL" />
      </geometry>
    </collision>
  </link>
  <joint
    name="ring_finger_joint1"
    type="continuous">
    <origin
      xyz="0.00730130112550688 0.276000000000004 0"
      rpy="0.338523687330689 0 0" />
    <parent
      link="ring_Link" />
    <child
      link="ring_mid_Link" />
    <axis
      xyz="1 0 0" />
  </joint>
  <link
    name="ring_top_Link">
    <inertial>
      <origin
        xyz="0.089117736388319 0.151845872486246 -1.45651650549361E-05"
        rpy="0 0 0" />
      <mass
        value="4.69702722195169" />
      <inertia
        ixx="0.0366670219730893"
        ixy="-5.7462778554955E-09"
        ixz="2.80296628531814E-10"
        iyy="0.0149637358445387"
        iyz="-6.98526079909341E-06"
        izz="0.0438601526716229" />
    </inertial>
    <visual>
      <origin
        xyz="0 0 0"
        rpy="0 0 0" />
      <geometry>
        <mesh
          filename="meshes/ring_top_Link.STL" />
      </geometry>
      <material
        name="">
        <color
          rgba="0.792156862745098 0.819607843137255 0.933333333333333 1" />
      </material>
    </visual>
    <collision>
      <origin
        xyz="0 0 0"
        rpy="0 0 0" />
      <geometry>
        <mesh
          filename="meshes/ring_top_Link.STL" />
      </geometry>
    </collision>
  </link>
  <joint
    name="ring_finger_joint2"
    type="continuous">
    <origin
      xyz="7.2516E-05 0.276 0"
      rpy="0.54187 0 0" />
    <parent
      link="ring_mid_Link" />
    <child
      link="ring_top_Link" />
    <axis
      xyz="1 0 0" />
  </joint>
  <link
    name="little_Link">
    <inertial>
      <origin
        xyz="0.0786469068891441 0.10287821601027 -2.62304138684832E-05"
        rpy="0 0 0" />
      <mass
        value="2.60908152503793" />
      <inertia
        ixx="0.010801877603534"
        ixy="-3.34579613299956E-09"
        ixz="-1.06293661220417E-09"
        iyy="0.00699045752408184"
        iyz="-3.98836075019026E-06"
        izz="0.0134727854714726" />
    </inertial>
    <visual>
      <origin
        xyz="0 0 0"
        rpy="0 0 0" />
      <geometry>
        <mesh
          filename="meshes/little_Link.STL" />
      </geometry>
      <material
        name="">
        <color
          rgba="0.298039215686275 0.298039215686275 0.298039215686275 1" />
      </material>
    </visual>
    <collision>
      <origin
        xyz="0 0 0"
        rpy="0 0 0" />
      <geometry>
        <mesh
          filename="meshes/little_Link.STL" />
      </geometry>
    </collision>
  </link>
  <joint
    name="little_palm"
    type="continuous">
    <origin
      xyz="0.297444647399156 0.0804178268004545 -1.18100000000001"
      rpy="-1.75471772732245 0 0" />
    <parent
      link="palm_link" />
    <child
      link="little_Link" />
    <axis
      xyz="1 0 0" />
  </joint>
  <link
    name="little_mid_Link">
    <inertial>
      <origin
        xyz="0.0780878080609607 0.0777171046498477 -3.67259529781699E-05"
        rpy="0 0 0" />
      <mass
        value="1.8633745178554" />
      <inertia
        ixx="0.00541773686778041"
        ixy="-2.19205383324963E-09"
        ixz="4.59631144317318E-10"
        iyy="0.00499175789357438"
        iyz="-2.45009465538378E-06"
        izz="0.00732032721276968" />
    </inertial>
    <visual>
      <origin
        xyz="0 0 0"
        rpy="0 0 0" />
      <geometry>
        <mesh
          filename="meshes/little_mid_Link.STL" />
      </geometry>
      <material
        name="">
        <color
          rgba="0.298039215686275 0.298039215686275 0.298039215686275 1" />
      </material>
    </visual>
    <collision>
      <origin
        xyz="0 0 0"
        rpy="0 0 0" />
      <geometry>
        <mesh
          filename="meshes/little_mid_Link.STL" />
      </geometry>
    </collision>
  </link>
  <joint
    name="little_finger_joint1"
    type="continuous">
    <origin
      xyz="0.000759098022390492 0.226000000000002 0"
      rpy="0.192675774139707 0 0" />
    <parent
      link="little_Link" />
    <child
      link="little_mid_Link" />
    <axis
      xyz="1 0 0" />
  </joint>
  <link
    name="little_top_Link">
    <inertial>
      <origin
        xyz="0.0790777457889324 0.148736186432886 -1.71307286805367E-05"
        rpy="0 0 0" />
      <mass
        value="3.99364097034048" />
      <inertia
        ixx="0.0292784936131837"
        ixy="-4.2698600285243E-09"
        ixz="2.16334064289563E-10"
        iyy="0.0107133514491663"
        iyz="-6.79522379971832E-06"
        izz="0.033393771594786" />
    </inertial>
    <visual>
      <origin
        xyz="0 0 0"
        rpy="0 0 0" />
      <geometry>
        <mesh
          filename="meshes/little_top_Link.STL" />
      </geometry>
      <material
        name="">
        <color
          rgba="0.792156862745098 0.819607843137255 0.933333333333333 1" />
      </material>
    </visual>
    <collision>
      <origin
        xyz="0 0 0"
        rpy="0 0 0" />
      <geometry>
        <mesh
          filename="meshes/little_top_Link.STL" />
      </geometry>
    </collision>
  </link>
  <joint
    name="little_finger_joint2"
    type="continuous">
    <origin
      xyz="-0.000789936725883233 0.176 0"
      rpy="0.443039889232053 0 0" />
    <parent
      link="little_mid_Link" />
    <child
      link="little_top_Link" />
    <axis
      xyz="1 0 0" />
  </joint>
</robot>